<?xml version="1.0" encoding="UTF-8"?>

<robot xmlns:xsi="http://www.w3.org/2001/XMLSchema-instance"
       xsi:noNamespaceSchemaLocation="URDF_CRPI.xsd"
       name="Fanuc-LRMate-200iD">

  <CrpiType>CrpiCrcl</CrpiType>

  <Debug>true</Debug>

  <TCP_IP Address="localhost" Port="64444" Client="false" />
  
  <ComType Val="TCP_IP"/>
  
  <!-- This is a robot-specific sections for a CRCL robot -->
  <CRCL_Robot>
    <Status_Request_Period>0.2</Status_Request_Period>
    <Command_Schema>CRCLCommandInstance.xsd</Command_Schema>
    <Status_Schema>CRCLStatus.xsd</Status_Schema>
  </CRCL_Robot>

  <Mounting X="0" Y="0" Z="0" XR="0" YR="0" ZR="0"/>

  <ToWorld X="0" Y="0" Z="0"
	   XR="0" YR="0" ZR="0"
	   M00="0" M01="0" M02="0" M03="0"
	   M10="0" M11="0" M12="0" M13="0"
	   M20="0" M21="0" M22="0" M23="0"
	   M30="0" M31="0" M32="0" M33="0"/> 

  <Tool ID="1" Name="Parallel" X="0" Y="0" Z="100"
	XR="0" YR="0" ZR="0"
	Mass="0.1" MX="0.1" MY="0.1" MZ="0.1"/> 

  <Tool ID="2" Name="Vacuum" X="0" Y="0" Z="100"
	XR="0" YR="0" ZR="0"
	Mass="0.1" MX="0.1" MY="0.1" MZ="0.1"/> 

  <link name="base_link">
    <visual>
      <origin rpy="0 0 0" xyz="0 0 0"/>
      <geometry>
	<mesh filename="package://fanuc_lrmate200id_support/meshes/lrmate200id/visual/base_link.stl"/>
      </geometry>
      <material name="">
	<color rgba="0.278431372549 0.278431372549 0.278431372549 1.0"/>
      </material>
    </visual>
    <collision>
      <origin rpy="0 0 0" xyz="0 0 0"/>
      <geometry>
	<mesh filename="package://fanuc_lrmate200id_support/meshes/lrmate200id/collision/base_link.stl"/>
      </geometry>
    </collision>
  </link>
  <link name="link_1">
    <visual>
      <origin rpy="0 0 0" xyz="0 0 0"/>
      <geometry>
	<mesh filename="package://fanuc_lrmate200id_support/meshes/lrmate200id/visual/link_1.stl"/>
      </geometry>
      <material name="">
	<color rgba="0.96 0.76 0.13 1.0"/>
      </material>
    </visual>
    <collision>
      <origin rpy="0 0 0" xyz="0 0 0"/>
      <geometry>
	<mesh filename="package://fanuc_lrmate200id_support/meshes/lrmate200id/collision/link_1.stl"/>
      </geometry>
    </collision>
  </link>
  <link name="link_2">
    <visual>
      <origin rpy="0 0 0" xyz="0 0 0"/>
      <geometry>
	<mesh filename="package://fanuc_lrmate200id_support/meshes/lrmate200id/visual/link_2.stl"/>
      </geometry>
      <material name="">
	<color rgba="0.96 0.76 0.13 1.0"/>
      </material>
    </visual>
    <collision>
      <origin rpy="0 0 0" xyz="0 0 0"/>
      <geometry>
	<mesh filename="package://fanuc_lrmate200id_support/meshes/lrmate200id/collision/link_2.stl"/>
      </geometry>
    </collision>
  </link>
  <link name="link_3">
    <visual>
      <origin rpy="0 0 0" xyz="0 0 0"/>
      <geometry>
	<mesh filename="package://fanuc_lrmate200id_support/meshes/lrmate200id/visual/link_3.stl"/>
      </geometry>
      <material name="">
	<color rgba="0.96 0.76 0.13 1.0"/>
      </material>
    </visual>
    <collision>
      <origin rpy="0 0 0" xyz="0 0 0"/>
      <geometry>
	<mesh filename="package://fanuc_lrmate200id_support/meshes/lrmate200id/collision/link_3.stl"/>
      </geometry>
    </collision>
  </link>
  <link name="link_4">
    <visual>
      <origin rpy="0 0 0" xyz="0 0 0"/>
      <geometry>
	<mesh filename="package://fanuc_lrmate200id_support/meshes/lrmate200id/visual/link_4.stl"/>
      </geometry>
      <material name="">
	<color rgba="0.96 0.76 0.13 1.0"/>
      </material>
    </visual>
    <collision>
      <origin rpy="0 0 0" xyz="0 0 0"/>
      <geometry>
	<mesh filename="package://fanuc_lrmate200id_support/meshes/lrmate200id/collision/link_4.stl"/>
      </geometry>
    </collision>
  </link>
  <link name="link_5">
    <visual>
      <origin rpy="0 0 0" xyz="0 0 0"/>
      <geometry>
	<mesh filename="package://fanuc_lrmate200id_support/meshes/lrmate200id/visual/link_5.stl"/>
      </geometry>
      <material name="">
	<color rgba="0.96 0.76 0.13 1.0"/>
      </material>
    </visual>
    <collision>
      <origin rpy="0 0 0" xyz="0 0 0"/>
      <geometry>
	<mesh filename="package://fanuc_lrmate200id_support/meshes/lrmate200id/collision/link_5.stl"/>
      </geometry>
    </collision>
  </link>
  <link name="link_6">
    <visual>
      <origin rpy="0 0 0" xyz="0 0 0"/>
      <geometry>
	<mesh filename="package://fanuc_lrmate200id_support/meshes/lrmate200id/visual/link_6.stl"/>
      </geometry>
      <material name="">
	<color rgba="0.15 0.15 0.15 1.0"/>
      </material>
    </visual>
    <collision>
      <origin rpy="0 0 0" xyz="0 0 0"/>
      <geometry>
	<mesh filename="package://fanuc_lrmate200id_support/meshes/lrmate200id/collision/link_6.stl"/>
      </geometry>
    </collision>
  </link>
  <!-- joints: main serial chain -->
  <joint name="joint_1" type="revolute">
    <origin rpy="0 0 0" xyz="0 0 0.330"/>
    <parent link="base_link"/>
    <child link="link_1"/>
    <axis xyz="0 0 1"/>
    <limit effort="0" lower="-2.965" upper="2.965" velocity="7.85"/>
  </joint>
  <joint name="joint_2" type="revolute">
    <origin rpy="0 0 0" xyz="0.050 0 0"/>
    <parent link="link_1"/>
    <child link="link_2"/>
    <axis xyz="0 1 0"/>
    <limit effort="0" lower="-1.745329" upper="2.530727" velocity="6.63"/>
  </joint>
  <joint name="joint_3" type="revolute">
    <origin rpy="0 0 0" xyz="0 0 0.330"/>
    <parent link="link_2"/>
    <child link="link_3"/>
    <axis xyz="0 -1 0"/>
    <limit effort="0" lower="-2.450966" upper="4.886922" velocity="9.08"/>
  </joint>
  <joint name="joint_4" type="revolute">
    <origin rpy="0 0 0" xyz="0 0 0.035"/>
    <parent link="link_3"/>
    <child link="link_4"/>
    <axis xyz="-1 0 0"/>
    <limit effort="0" lower="-3.315" upper="3.315" velocity="9.60"/>
  </joint>
  <joint name="joint_5" type="revolute">
    <origin rpy="0 0 0" xyz="0.335 0 0"/>
    <parent link="link_4"/>
    <child link="link_5"/>
    <axis xyz="0 -1 0"/>
    <limit effort="0" lower="-2.18" upper="2.18" velocity="9.51"/>
  </joint>
  <joint name="joint_6" type="revolute">
    <origin rpy="0 0 0" xyz="0.080 0 0"/>
    <parent link="link_5"/>
    <child link="link_6"/>
    <axis xyz="-1 0 0"/>
    <limit effort="0" lower="-6.285" upper="6.285" velocity="17.45"/>
  </joint>

</robot>

